<mujoco model="base">
  <compiler angle="radian" meshdir="meshes/"/>
  <option impratio="20" density="1.2" viscosity="2e-05" cone="elliptic"/>
  <size njmax="5000" nconmax="5000"/>
  <visual>
    <map znear="0.001"/>
  </visual>
  <statistic meansize="0.194254" extent="10.6098" center="1.11639 0 1.5"/>
  <asset>
    <texture type="skybox" builtin="gradient" rgb1="0.9 0.9 1" rgb2="0.2 0.3 0.4" width="256" height="1536"/>
    <texture type="2d" name="texplane" file="/Users/mirujun/robosuite/robosuite/models/assets/arenas/../textures/light-gray-floor-tile.png"/>
    <texture type="cube" name="tex-ceramic" file="/Users/mirujun/robosuite/robosuite/models/assets/arenas/../textures/ceramic.png"/>
    <texture type="cube" name="tex-steel-brushed" file="/Users/mirujun/robosuite/robosuite/models/assets/arenas/../textures/steel-brushed.png"/>
    <texture type="2d" name="tex-light-gray-plaster" file="/Users/mirujun/robosuite/robosuite/models/assets/arenas/../textures/light-gray-plaster.png"/>
    <texture type="cube" name="textable" builtin="flat" rgb1="0.5 0.5 0.5" width="512" height="3072"/>
    <texture type="cube" name="cube_redwood" file="/Users/mirujun/robosuite/robosuite/models/assets/textures/red-wood.png"/>
    <texture type="skybox" name="bottle_tex-glass" file="/Users/mirujun/robosuite/robosuite/models/assets/objects/../textures/glass.png"/>
    <material name="floorplane" texture="texplane" texuniform="true" texrepeat="2 2" specular="0" shininess="0" reflectance="0.01"/>
    <material name="table_ceramic" texture="tex-ceramic" specular="0.2" shininess="0"/>
    <material name="table_legs_metal" texture="tex-steel-brushed" shininess="0.8" reflectance="0.8"/>
    <material name="walls_mat" texture="tex-light-gray-plaster" texuniform="true" texrepeat="3 3" specular="0.1" shininess="0.1"/>
    <material name="table_mat" texture="textable"/>
    <material name="robot0_Mtl1.017" shininess="0.225" rgba="1 0 0 1"/>
    <material name="robot0_Mtl2.017" shininess="0.225" rgba="0.286275 0.286275 0.286275 1"/>
    <material name="robot0_Mtl1" shininess="0.225" rgba="1 0 0 1"/>
    <material name="robot0_Mtl2" shininess="0.225" rgba="0 0 0 1"/>
    <material name="robot0_Mtl4" shininess="0.225"/>
    <material name="robot0_Mtl5" shininess="0.225" rgba="0.870588 0.309804 0.086275 1"/>
    <material name="robot0_Mtl6" shininess="0.225" rgba="0.286275 0.286275 0.286275 1"/>
    <material name="robot0_Mtl7" shininess="0.225" rgba="0.698039 0.698039 0.698039 1"/>
    <material name="robot0_Mtl8" shininess="0.225" rgba="0.792157 0.819608 0.929412 1"/>
    <material name="robot0_Mtl9" shininess="0.225" rgba="0.25098 0.25098 0.25098 1"/>
    <material name="robot0_Mtla" shininess="0.225" rgba="0 0 1 1"/>
    <material name="robot0_Mtlb" shininess="0.225" rgba="0.290196 0.290196 0.290196 1"/>
    <material name="robot0_Mtl1.014" shininess="0.225" rgba="0.286275 0.286275 0.286275 1"/>
    <material name="robot0_Mtl2.014" shininess="0.225"/>
    <material name="robot0_Mtl3.013" shininess="0.225" rgba="0.168627 0.152941 0.141176 1"/>
    <material name="robot0_Mtl4.012" shininess="0.225" rgba="1 0.403922 0.121569 1"/>
    <material name="robot0_Mtl5.010" shininess="0.225" rgba="1 0 0 1"/>
    <material name="robot0_Mtl6.008" shininess="0.225" rgba="0.792157 0.819608 0.929412 1"/>
    <material name="robot0_Mtl7.007" shininess="0.225" rgba="0.25098 0.25098 0.25098 1"/>
    <material name="robot0_Mtl1.004" shininess="0.225"/>
    <material name="robot0_Mtl2.004" shininess="0.225" rgba="1 0 0 1"/>
    <material name="robot0_Mtl3.003" shininess="0.225" rgba="0.286275 0.286275 0.286275 1"/>
    <material name="robot0_Mtl1.005" shininess="0.225" rgba="1 0 0 1"/>
    <material name="robot0_Mtl2.005" shininess="0.225" rgba="0.286275 0.286275 0.286275 1"/>
    <material name="robot0_Mtl3.004" shininess="0.225"/>
    <material name="robot0_Mtl4.003" shininess="0.225" rgba="0.792157 0.819608 0.929412 1"/>
    <material name="robot0_Mtl5.003" shininess="0.225" rgba="0.105882 0.105882 0.105882 1"/>
    <material name="robot0_Mtl1.007" shininess="0.225" rgba="0.290196 0.290196 0.290196 1"/>
    <material name="robot0_Mtl2.007" shininess="0.225"/>
    <material name="robot0_Mtl3.006" shininess="0.225" rgba="1 0 0 1"/>
    <material name="robot0_Mtl4.005" shininess="0.225" rgba="0.792157 0.819608 0.929412 1"/>
    <material name="robot0_Mtl1.010" shininess="0.225" rgba="0.286275 0.286275 0.286275 1"/>
    <material name="robot0_Mtl2.010" shininess="0.225" rgba="1 0 0 1"/>
    <material name="robot0_Mtl3.009" shininess="0.225" rgba="0 0 0 1"/>
    <material name="robot0_Mtl4.008" shininess="0.225" rgba="0.792157 0.819608 0.929412 1"/>
    <material name="robot0_Mtl5.006" shininess="0.225"/>
    <material name="robot0_Mtl6.004" shininess="0.225" rgba="0.74902 0.74902 0.74902 1"/>
    <material name="robot0_Mtl7.004" shininess="0.225" rgba="0.290196 0.290196 0.290196 1"/>
    <material name="robot0_Mtl8.002" shininess="0.225" rgba="0.25098 0.25098 0.25098 1"/>
    <material name="robot0_Mtl1_001" shininess="0.225" rgba="1 0 0 1"/>
    <material name="robot0_Mtl2_001" shininess="0.225"/>
    <material name="robot0_Mtl3_001" shininess="0.225" rgba="0.286275 0.286275 0.286275 1"/>
    <material name="robot0_Mtl4_001" shininess="0.225" rgba="0.866667 0.905882 1 1"/>
    <material name="robot0_Mtl5_001" shininess="0.225" rgba="0.501961 0.501961 0.501961 1"/>
    <material name="robot0_Mtl1.012" shininess="0.225" rgba="0.298039 0.298039 0.298039 1"/>
    <material name="robot0_Mtl2.012" shininess="0.225" rgba="0.282353 0.282353 0.282353 1"/>
    <material name="robot0_Mtl3.011" shininess="0.225" rgba="0.286275 0.286275 0.286275 1"/>
    <material name="robot0_Mtl4.010" shininess="0.225" rgba="1 0 0 1"/>
    <material name="robot0_Mtl5.008" shininess="0.225"/>
    <material name="robot0_Mtl6.006" shininess="0.225" rgba="1 0.403922 0.121569 1"/>
    <material name="gripper0_Material_001.001" shininess="0.25" rgba="0.64 0 0 1"/>
    <material name="gripper0_Material_002" shininess="0.25" rgba="0.64 0.64 0.64 1"/>
    <material name="gripper0_finger_mat" shininess="0.25" rgba="0 0 0 1"/>
    <material name="gripper0_Material_001" shininess="0.25" rgba="0.001651 0.001651 0.001651 1"/>
    <material name="cube_redwood_mat" texture="cube_redwood" specular="0.4" shininess="0.1"/>
    <material name="bottle_glass" texture="bottle_tex-glass" texuniform="true" texrepeat="5 5" reflectance="0.5"/>
    <mesh name="robot0_base_0" file="/Users/mirujun/robosuite/robosuite/models/assets/robots/sawyer/obj_meshes/base/base_0.obj"/>
    <mesh name="robot0_base_1" file="/Users/mirujun/robosuite/robosuite/models/assets/robots/sawyer/obj_meshes/base/base_1.obj"/>
    <mesh name="robot0_head_0" file="/Users/mirujun/robosuite/robosuite/models/assets/robots/sawyer/obj_meshes/head/head_0.obj"/>
    <mesh name="robot0_head_1" file="/Users/mirujun/robosuite/robosuite/models/assets/robots/sawyer/obj_meshes/head/head_1.obj"/>
    <mesh name="robot0_head_2" file="/Users/mirujun/robosuite/robosuite/models/assets/robots/sawyer/obj_meshes/head/head_2.obj"/>
    <mesh name="robot0_head_3" file="/Users/mirujun/robosuite/robosuite/models/assets/robots/sawyer/obj_meshes/head/head_3.obj"/>
    <mesh name="robot0_head_4" file="/Users/mirujun/robosuite/robosuite/models/assets/robots/sawyer/obj_meshes/head/head_4.obj"/>
    <mesh name="robot0_head_5" file="/Users/mirujun/robosuite/robosuite/models/assets/robots/sawyer/obj_meshes/head/head_5.obj"/>
    <mesh name="robot0_head_6" file="/Users/mirujun/robosuite/robosuite/models/assets/robots/sawyer/obj_meshes/head/head_6.obj"/>
    <mesh name="robot0_head_7" file="/Users/mirujun/robosuite/robosuite/models/assets/robots/sawyer/obj_meshes/head/head_7.obj"/>
    <mesh name="robot0_head_8" file="/Users/mirujun/robosuite/robosuite/models/assets/robots/sawyer/obj_meshes/head/head_8.obj"/>
    <mesh name="robot0_head_9" file="/Users/mirujun/robosuite/robosuite/models/assets/robots/sawyer/obj_meshes/head/head_9.obj"/>
    <mesh name="robot0_l0_0" file="/Users/mirujun/robosuite/robosuite/models/assets/robots/sawyer/obj_meshes/l0/l0_0.obj"/>
    <mesh name="robot0_l0_1" file="/Users/mirujun/robosuite/robosuite/models/assets/robots/sawyer/obj_meshes/l0/l0_1.obj"/>
    <mesh name="robot0_l0_2" file="/Users/mirujun/robosuite/robosuite/models/assets/robots/sawyer/obj_meshes/l0/l0_2.obj"/>
    <mesh name="robot0_l0_3" file="/Users/mirujun/robosuite/robosuite/models/assets/robots/sawyer/obj_meshes/l0/l0_3.obj"/>
    <mesh name="robot0_l0_4" file="/Users/mirujun/robosuite/robosuite/models/assets/robots/sawyer/obj_meshes/l0/l0_4.obj"/>
    <mesh name="robot0_l0_5" file="/Users/mirujun/robosuite/robosuite/models/assets/robots/sawyer/obj_meshes/l0/l0_5.obj"/>
    <mesh name="robot0_l0_6" file="/Users/mirujun/robosuite/robosuite/models/assets/robots/sawyer/obj_meshes/l0/l0_6.obj"/>
    <mesh name="robot0_l1_0" file="/Users/mirujun/robosuite/robosuite/models/assets/robots/sawyer/obj_meshes/l1/l1_0.obj"/>
    <mesh name="robot0_l1_1" file="/Users/mirujun/robosuite/robosuite/models/assets/robots/sawyer/obj_meshes/l1/l1_1.obj"/>
    <mesh name="robot0_l1_2" file="/Users/mirujun/robosuite/robosuite/models/assets/robots/sawyer/obj_meshes/l1/l1_2.obj"/>
    <mesh name="robot0_l2_0" file="/Users/mirujun/robosuite/robosuite/models/assets/robots/sawyer/obj_meshes/l2/l2_0.obj"/>
    <mesh name="robot0_l2_1" file="/Users/mirujun/robosuite/robosuite/models/assets/robots/sawyer/obj_meshes/l2/l2_1.obj"/>
    <mesh name="robot0_l2_2" file="/Users/mirujun/robosuite/robosuite/models/assets/robots/sawyer/obj_meshes/l2/l2_2.obj"/>
    <mesh name="robot0_l2_3" file="/Users/mirujun/robosuite/robosuite/models/assets/robots/sawyer/obj_meshes/l2/l2_3.obj"/>
    <mesh name="robot0_l2_4" file="/Users/mirujun/robosuite/robosuite/models/assets/robots/sawyer/obj_meshes/l2/l2_4.obj"/>
    <mesh name="robot0_l3_0" file="/Users/mirujun/robosuite/robosuite/models/assets/robots/sawyer/obj_meshes/l3/l3_0.obj"/>
    <mesh name="robot0_l3_1" file="/Users/mirujun/robosuite/robosuite/models/assets/robots/sawyer/obj_meshes/l3/l3_1.obj"/>
    <mesh name="robot0_l3_2" file="/Users/mirujun/robosuite/robosuite/models/assets/robots/sawyer/obj_meshes/l3/l3_2.obj"/>
    <mesh name="robot0_l3_3" file="/Users/mirujun/robosuite/robosuite/models/assets/robots/sawyer/obj_meshes/l3/l3_3.obj"/>
    <mesh name="robot0_l4_0" file="/Users/mirujun/robosuite/robosuite/models/assets/robots/sawyer/obj_meshes/l4/l4_0.obj"/>
    <mesh name="robot0_l4_1" file="/Users/mirujun/robosuite/robosuite/models/assets/robots/sawyer/obj_meshes/l4/l4_1.obj"/>
    <mesh name="robot0_l4_2" file="/Users/mirujun/robosuite/robosuite/models/assets/robots/sawyer/obj_meshes/l4/l4_2.obj"/>
    <mesh name="robot0_l4_3" file="/Users/mirujun/robosuite/robosuite/models/assets/robots/sawyer/obj_meshes/l4/l4_3.obj"/>
    <mesh name="robot0_l4_4" file="/Users/mirujun/robosuite/robosuite/models/assets/robots/sawyer/obj_meshes/l4/l4_4.obj"/>
    <mesh name="robot0_l4_5" file="/Users/mirujun/robosuite/robosuite/models/assets/robots/sawyer/obj_meshes/l4/l4_5.obj"/>
    <mesh name="robot0_l4_6" file="/Users/mirujun/robosuite/robosuite/models/assets/robots/sawyer/obj_meshes/l4/l4_6.obj"/>
    <mesh name="robot0_l4_7" file="/Users/mirujun/robosuite/robosuite/models/assets/robots/sawyer/obj_meshes/l4/l4_7.obj"/>
    <mesh name="robot0_l5_0" file="/Users/mirujun/robosuite/robosuite/models/assets/robots/sawyer/obj_meshes/l5/l5_0.obj"/>
    <mesh name="robot0_l5_1" file="/Users/mirujun/robosuite/robosuite/models/assets/robots/sawyer/obj_meshes/l5/l5_1.obj"/>
    <mesh name="robot0_l5_2" file="/Users/mirujun/robosuite/robosuite/models/assets/robots/sawyer/obj_meshes/l5/l5_2.obj"/>
    <mesh name="robot0_l5_3" file="/Users/mirujun/robosuite/robosuite/models/assets/robots/sawyer/obj_meshes/l5/l5_3.obj"/>
    <mesh name="robot0_l5_4" file="/Users/mirujun/robosuite/robosuite/models/assets/robots/sawyer/obj_meshes/l5/l5_4.obj"/>
    <mesh name="robot0_l6_0" file="/Users/mirujun/robosuite/robosuite/models/assets/robots/sawyer/obj_meshes/l6/l6_0.obj"/>
    <mesh name="robot0_l6_1" file="/Users/mirujun/robosuite/robosuite/models/assets/robots/sawyer/obj_meshes/l6/l6_1.obj"/>
    <mesh name="robot0_l6_2" file="/Users/mirujun/robosuite/robosuite/models/assets/robots/sawyer/obj_meshes/l6/l6_2.obj"/>
    <mesh name="robot0_l6_3" file="/Users/mirujun/robosuite/robosuite/models/assets/robots/sawyer/obj_meshes/l6/l6_3.obj"/>
    <mesh name="robot0_l6_4" file="/Users/mirujun/robosuite/robosuite/models/assets/robots/sawyer/obj_meshes/l6/l6_4.obj"/>
    <mesh name="robot0_l6_5" file="/Users/mirujun/robosuite/robosuite/models/assets/robots/sawyer/obj_meshes/l6/l6_5.obj"/>
    <mesh name="mount0_pedestal" file="/Users/mirujun/robosuite/robosuite/models/assets/mounts/meshes/rethink_mount/pedestal.stl"/>
    <mesh name="gripper0_standard_narrow" file="/Users/mirujun/robosuite/robosuite/models/assets/grippers/meshes/rethink_gripper/standard_narrow.stl"/>
    <mesh name="gripper0_half_round_tip" file="/Users/mirujun/robosuite/robosuite/models/assets/grippers/meshes/rethink_gripper/half_round_tip.stl"/>
    <mesh name="gripper0_electric_gripper_base_0" file="/Users/mirujun/robosuite/robosuite/models/assets/grippers/obj_meshes/rethink_gripper/electric_gripper_base/electric_gripper_base_0.obj"/>
    <mesh name="gripper0_electric_gripper_base_1" file="/Users/mirujun/robosuite/robosuite/models/assets/grippers/obj_meshes/rethink_gripper/electric_gripper_base/electric_gripper_base_1.obj"/>
    <mesh name="gripper0_connector_plate" file="/Users/mirujun/robosuite/robosuite/models/assets/grippers/obj_meshes/rethink_gripper/connector_plate/connector_plate.obj"/>
    <mesh name="bottle_mesh" file="/Users/mirujun/robosuite/robosuite/models/assets/objects/meshes/bottle.stl"/>
  </asset>
  <worldbody>
    <geom name="floor" size="3 3 0.125" type="plane" group="1" material="floorplane"/>
    <geom name="wall_leftcorner_visual" size="1.06 1.5 0.01" pos="-1.25 2.25 1.5" quat="0.653281 0.653281 0.270598 0.270598" type="box" contype="0" conaffinity="0" group="1" material="walls_mat"/>
    <geom name="wall_rightcorner_visual" size="1.06 1.5 0.01" pos="-1.25 -2.25 1.5" quat="0.653281 0.653281 -0.270598 -0.270598" type="box" contype="0" conaffinity="0" group="1" material="walls_mat"/>
    <geom name="wall_left_visual" size="1.75 1.5 0.01" pos="1.25 3 1.5" quat="0.707107 0.707107 0 0" type="box" contype="0" conaffinity="0" group="1" material="walls_mat"/>
    <geom name="wall_right_visual" size="1.75 1.5 0.01" pos="1.25 -3 1.5" quat="0.707107 -0.707107 0 0" type="box" contype="0" conaffinity="0" group="1" material="walls_mat"/>
    <geom name="wall_rear_visual" size="1.5 1.5 0.01" pos="-2 0 1.5" quat="0.5 0.5 0.5 0.5" type="box" contype="0" conaffinity="0" group="1" material="walls_mat"/>
    <geom name="wall_front_visual" size="3 1.5 0.01" pos="3 0 1.5" quat="0.5 0.5 -0.5 -0.5" type="box" contype="0" conaffinity="0" group="1" material="walls_mat"/>
    <camera name="frontview" pos="1.6 0 1.45" quat="0.560842 0.430646 0.430646 0.560842"/>
    <camera name="birdview" pos="-0.2 0 3" quat="0.707107 0 0 0.707107"/>
    <camera name="agentview" pos="0.5 0 1.35" quat="0.653098 0.271041 0.271041 0.653098"/>
    <camera name="sideview" pos="-0.0565177 1.27612 1.48796" quat="0.00990507 0.00687796 0.591223 0.806418"/>
    <light pos="1 1 1.5" dir="-0.19245 -0.19245 -0.96225" directional="true" castshadow="false"/>
    <body name="table" pos="0 0 0.775">
      <geom name="table_collision" size="0.4 0.4 0.025" type="box" rgba="0.5 0.5 0 1"/>
      <geom name="table_visual" size="0.4 0.4 0.025" type="box" contype="0" conaffinity="0" group="1" material="table_ceramic"/>
      <geom name="table_leg1_visual" size="0.025 0.3875" pos="0.3 0.3 -0.3875" type="cylinder" contype="0" conaffinity="0" group="1" material="table_legs_metal"/>
      <geom name="table_leg2_visual" size="0.025 0.3875" pos="-0.3 0.3 -0.3875" type="cylinder" contype="0" conaffinity="0" group="1" material="table_legs_metal"/>
      <geom name="table_leg3_visual" size="0.025 0.3875" pos="-0.3 -0.3 -0.3875" type="cylinder" contype="0" conaffinity="0" group="1" material="table_legs_metal"/>
      <geom name="table_leg4_visual" size="0.025 0.3875" pos="0.3 -0.3 -0.3875" type="cylinder" contype="0" conaffinity="0" group="1" material="table_legs_metal"/>
      <site name="table_top" pos="0 0 0.025" size="0.001" rgba="0 0 0 0"/>
    </body>
    <body name="robot0_base" pos="-0.56 0 0.912">
      <inertial pos="0 0 0" mass="0" diaginertia="0 0 0"/>
      <camera name="robot0_robotview" pos="1 0 0.4" quat="0.653098 0.271041 0.271041 0.653098"/>
      <body name="robot0_right_arm_base_link">
        <inertial pos="-0.0006241 -2.8025e-05 0.065404" quat="-0.209285 0.674441 0.227335 0.670558" mass="2.0687" diaginertia="0.00740351 0.00681776 0.00672942"/>
        <geom name="robot0_g0_vis" type="mesh" contype="0" conaffinity="0" group="1" material="robot0_Mtl2.017" mesh="robot0_base_0"/>
        <geom name="robot0_g1_vis" type="mesh" contype="0" conaffinity="0" group="1" material="robot0_Mtl1.017" mesh="robot0_base_1"/>
        <geom name="robot0_base_col" size="0.08 0.12" pos="0 0 0.12" type="cylinder" rgba="0 0.5 0 1"/>
        <body name="robot0_right_l0" pos="0 0 0.08">
          <inertial pos="0.024366 0.010969 0.14363" quat="0.894823 0.00899958 -0.170275 0.412573" mass="5.3213" diaginertia="0.0651588 0.0510944 0.0186218"/>
          <joint name="robot0_right_j0" pos="0 0 0" axis="0 0 1" range="-3.0503 3.0503" armature="5" damping="0.1" frictionloss="0.1"/>
          <geom name="robot0_g2_vis" type="mesh" contype="0" conaffinity="0" group="1" material="robot0_Mtl7.007" mesh="robot0_l0_0"/>
          <geom name="robot0_g3_vis" type="mesh" contype="0" conaffinity="0" group="1" material="robot0_Mtl6.008" mesh="robot0_l0_1"/>
          <geom name="robot0_g4_vis" type="mesh" contype="0" conaffinity="0" group="1" material="robot0_Mtl5.010" mesh="robot0_l0_2"/>
          <geom name="robot0_g5_vis" type="mesh" contype="0" conaffinity="0" group="1" material="robot0_Mtl4.012" mesh="robot0_l0_3"/>
          <geom name="robot0_g6_vis" type="mesh" contype="0" conaffinity="0" group="1" material="robot0_Mtl3.013" mesh="robot0_l0_4"/>
          <geom name="robot0_g7_vis" type="mesh" contype="0" conaffinity="0" group="1" material="robot0_Mtl2.014" mesh="robot0_l0_5"/>
          <geom name="robot0_g8_vis" type="mesh" contype="0" conaffinity="0" group="1" material="robot0_Mtl1.014" mesh="robot0_l0_6"/>
          <geom name="robot0_link0_collision" size="0.07" pos="0.08 0 0.23" rgba="0 0.5 0 1"/>
          <body name="robot0_head" pos="0 0 0.2965">
            <inertial pos="0.0053207 -2.6549e-05 0.1021" quat="0.999993 7.08405e-05 -0.00359857 -0.000626247" mass="1.5795" diaginertia="0.0118334 0.00827089 0.00496574"/>
            <geom name="robot0_g9_vis" type="mesh" contype="0" conaffinity="0" group="1" material="robot0_Mtlb" mesh="robot0_head_0"/>
            <geom name="robot0_g10_vis" type="mesh" contype="0" conaffinity="0" group="1" material="robot0_Mtla" mesh="robot0_head_1"/>
            <geom name="robot0_g11_vis" type="mesh" contype="0" conaffinity="0" group="1" material="robot0_Mtl8" mesh="robot0_head_2"/>
            <geom name="robot0_g12_vis" type="mesh" contype="0" conaffinity="0" group="1" material="robot0_Mtl9" mesh="robot0_head_3"/>
            <geom name="robot0_g13_vis" type="mesh" contype="0" conaffinity="0" group="1" material="robot0_Mtl7" mesh="robot0_head_4"/>
            <geom name="robot0_g14_vis" type="mesh" contype="0" conaffinity="0" group="1" material="robot0_Mtl6" mesh="robot0_head_5"/>
            <geom name="robot0_g15_vis" type="mesh" contype="0" conaffinity="0" group="1" material="robot0_Mtl4" mesh="robot0_head_6"/>
            <geom name="robot0_g16_vis" type="mesh" contype="0" conaffinity="0" group="1" material="robot0_Mtl2" mesh="robot0_head_7"/>
            <geom name="robot0_g17_vis" type="mesh" contype="0" conaffinity="0" group="1" material="robot0_Mtl1" mesh="robot0_head_8"/>
            <geom name="robot0_g18_vis" type="mesh" contype="0" conaffinity="0" group="1" material="robot0_Mtl5" mesh="robot0_head_9"/>
            <geom name="robot0_head_collision" size="0.018" pos="0 0 0.08" rgba="0 0.5 0 1"/>
            <body name="robot0_screen" pos="0.03 0 0.105" quat="0.5 0.5 0.5 0.5">
              <inertial pos="0 0 0" mass="0.0001" diaginertia="1e-08 1e-08 1e-08"/>
              <geom name="robot0_screen_collision" size="0.001" rgba="0 0.5 0 1"/>
            </body>
            <body name="robot0_head_camera" pos="0.0228027 0 0.216572" quat="0.342813 -0.618449 0.618449 -0.342813">
              <inertial pos="0.0228027 0 0.216572" quat="0.342813 -0.618449 0.618449 -0.342813" mass="0" diaginertia="0 0 0"/>
            </body>
          </body>
          <body name="robot0_right_torso_itb" pos="-0.055 0 0.22" quat="0.707107 0 -0.707107 0">
            <inertial pos="0 0 0" mass="0.0001" diaginertia="1e-08 1e-08 1e-08"/>
          </body>
          <body name="robot0_right_l1" pos="0.081 0.05 0.237" quat="0.5 -0.5 0.5 0.5">
            <inertial pos="-0.0030849 -0.026811 0.092521" quat="0.424888 0.891987 0.132364 -0.0794296" mass="4.505" diaginertia="0.0224339 0.0221624 0.0097097"/>
            <joint name="robot0_right_j1" pos="0 0 0" axis="0 0 1" range="-3.8095 2.2736" armature="2.5" damping="0.1" frictionloss="0.1"/>
            <geom name="robot0_g19_vis" type="mesh" contype="0" conaffinity="0" group="1" material="robot0_Mtl3.003" mesh="robot0_l1_0"/>
            <geom name="robot0_g20_vis" type="mesh" contype="0" conaffinity="0" group="1" material="robot0_Mtl2.004" mesh="robot0_l1_1"/>
            <geom name="robot0_g21_vis" type="mesh" contype="0" conaffinity="0" group="1" material="robot0_Mtl1.004" mesh="robot0_l1_2"/>
            <geom name="robot0_link1_collision" size="0.07" pos="0 0 0.1225" rgba="0 0.5 0 1"/>
            <body name="robot0_right_l2" pos="0 -0.14 0.1425" quat="0.707107 0.707107 0 0">
              <inertial pos="-0.00016044 -0.014967 0.13582" quat="0.707831 -0.0524761 0.0516007 0.702537" mass="1.745" diaginertia="0.0257928 0.025506 0.00292515"/>
              <joint name="robot0_right_j2" pos="0 0 0" axis="0 0 1" range="-3.0426 3.0426" armature="1.66667" damping="0.1" frictionloss="0.1"/>
              <geom name="robot0_g22_vis" type="mesh" contype="0" conaffinity="0" group="1" material="robot0_Mtl4.003" mesh="robot0_l2_0"/>
              <geom name="robot0_g23_vis" type="mesh" contype="0" conaffinity="0" group="1" material="robot0_Mtl5.003" mesh="robot0_l2_1"/>
              <geom name="robot0_g24_vis" type="mesh" contype="0" conaffinity="0" group="1" material="robot0_Mtl3.004" mesh="robot0_l2_2"/>
              <geom name="robot0_g25_vis" type="mesh" contype="0" conaffinity="0" group="1" material="robot0_Mtl2.005" mesh="robot0_l2_3"/>
              <geom name="robot0_g26_vis" type="mesh" contype="0" conaffinity="0" group="1" material="robot0_Mtl1.005" mesh="robot0_l2_4"/>
              <geom name="robot0_link2_collision" size="0.06 0.17" pos="0 0 0.08" type="cylinder" rgba="0 0.5 0 1"/>
              <body name="robot0_right_l3" pos="0 -0.042 0.26" quat="0.707107 -0.707107 0 0">
                <inertial pos="-0.0048135 -0.0281 -0.084154" quat="0.902999 0.385391 -0.0880901 0.168247" mass="2.5097" diaginertia="0.0102404 0.0096997 0.00369622"/>
                <joint name="robot0_right_j3" pos="0 0 0" axis="0 0 1" range="-3.0439 3.0439" armature="1.25" damping="0.1" frictionloss="0.1"/>
                <geom name="robot0_g27_vis" type="mesh" contype="0" conaffinity="0" group="1" material="robot0_Mtl4.005" mesh="robot0_l3_0"/>
                <geom name="robot0_g28_vis" type="mesh" contype="0" conaffinity="0" group="1" material="robot0_Mtl3.006" mesh="robot0_l3_1"/>
                <geom name="robot0_g29_vis" type="mesh" contype="0" conaffinity="0" group="1" material="robot0_Mtl2.007" mesh="robot0_l3_2"/>
                <geom name="robot0_g30_vis" type="mesh" contype="0" conaffinity="0" group="1" material="robot0_Mtl1.007" mesh="robot0_l3_3"/>
                <geom name="robot0_link3_collision" size="0.06" pos="0 -0.01 -0.12" rgba="0 0.5 0 1"/>
                <body name="robot0_right_l4" pos="0 -0.125 -0.1265" quat="0.707107 0.707107 0 0">
                  <inertial pos="-0.0018844 0.0069001 0.1341" quat="0.803612 0.031257 -0.0298334 0.593582" mass="1.1136" diaginertia="0.0136549 0.0135493 0.00127353"/>
                  <joint name="robot0_right_j4" pos="0 0 0" axis="0 0 1" range="-2.9761 2.9761" armature="1" damping="0.1" frictionloss="0.1"/>
                  <geom name="robot0_g31_vis" type="mesh" contype="0" conaffinity="0" group="1" material="robot0_Mtl8.002" mesh="robot0_l4_0"/>
                  <geom name="robot0_g32_vis" type="mesh" contype="0" conaffinity="0" group="1" material="robot0_Mtl7.004" mesh="robot0_l4_1"/>
                  <geom name="robot0_g33_vis" type="mesh" contype="0" conaffinity="0" group="1" material="robot0_Mtl6.004" mesh="robot0_l4_2"/>
                  <geom name="robot0_g34_vis" type="mesh" contype="0" conaffinity="0" group="1" material="robot0_Mtl5.006" mesh="robot0_l4_3"/>
                  <geom name="robot0_g35_vis" type="mesh" contype="0" conaffinity="0" group="1" material="robot0_Mtl4.008" mesh="robot0_l4_4"/>
                  <geom name="robot0_g36_vis" type="mesh" contype="0" conaffinity="0" group="1" material="robot0_Mtl3.009" mesh="robot0_l4_5"/>
                  <geom name="robot0_g37_vis" type="mesh" contype="0" conaffinity="0" group="1" material="robot0_Mtl2.010" mesh="robot0_l4_6"/>
                  <geom name="robot0_g38_vis" type="mesh" contype="0" conaffinity="0" group="1" material="robot0_Mtl1.010" mesh="robot0_l4_7"/>
                  <geom name="robot0_link4_collision" size="0.045 0.15" pos="0 0 0.11" type="cylinder" rgba="0 0.5 0 1"/>
                  <body name="robot0_right_arm_itb" pos="-0.055 0 0.075" quat="0.707107 0 -0.707107 0">
                    <inertial pos="0 0 0" mass="0.0001" diaginertia="1e-08 1e-08 1e-08"/>
                  </body>
                  <body name="robot0_right_l5" pos="0 0.031 0.275" quat="0.707107 -0.707107 0 0">
                    <inertial pos="0.0061133 -0.023697 0.076416" quat="0.404076 0.9135 0.0473125 0.00158335" mass="1.5625" diaginertia="0.00474131 0.00422857 0.00190672"/>
                    <joint name="robot0_right_j5" pos="0 0 0" axis="0 0 1" range="-2.9761 2.9761" armature="0.833333" damping="0.2" frictionloss="0.1"/>
                    <geom name="robot0_g39_vis" type="mesh" contype="0" conaffinity="0" group="1" material="robot0_Mtl5_001" mesh="robot0_l5_0"/>
                    <geom name="robot0_g40_vis" type="mesh" contype="0" conaffinity="0" group="1" material="robot0_Mtl4_001" mesh="robot0_l5_1"/>
                    <geom name="robot0_g41_vis" type="mesh" contype="0" conaffinity="0" group="1" material="robot0_Mtl2_001" mesh="robot0_l5_2"/>
                    <geom name="robot0_g42_vis" type="mesh" contype="0" conaffinity="0" group="1" material="robot0_Mtl1_001" mesh="robot0_l5_3"/>
                    <geom name="robot0_g43_vis" type="mesh" contype="0" conaffinity="0" group="1" material="robot0_Mtl3_001" mesh="robot0_l5_4"/>
                    <geom name="robot0_link5_collision" size="0.06" pos="0 0 0.1" rgba="0 0.5 0 1"/>
                    <body name="robot0_right_hand_camera" pos="0.039552 -0.033 0.0695" quat="0.707107 0 0.707107 0">
                      <inertial pos="0.039552 -0.033 0.0695" quat="0.707107 0 0.707107 0" mass="0" diaginertia="0 0 0"/>
                    </body>
                    <body name="robot0_right_wrist" pos="0 0 0.10541" quat="0.707107 0.707107 0 0">
                      <inertial pos="0 0 0.10541" quat="0.707107 0.707107 0 0" mass="0" diaginertia="0 0 0"/>
                    </body>
                    <body name="robot0_right_l6" pos="0 -0.11 0.1053" quat="0.0616248 0.06163 -0.704416 0.704416">
                      <inertial pos="-8.0726e-06 0.0085838 -0.0049566" quat="0.479044 0.515636 -0.513069 0.491322" mass="0.3292" diaginertia="0.000360258 0.000311068 0.000214974"/>
                      <joint name="robot0_right_j6" pos="0 0 0" axis="0 0 1" range="-4.7124 4.7124" armature="0.714286" damping="0.1" frictionloss="0.1"/>
                      <geom name="robot0_g44_vis" type="mesh" contype="0" conaffinity="0" group="1" material="robot0_Mtl6.006" mesh="robot0_l6_0"/>
                      <geom name="robot0_g45_vis" type="mesh" contype="0" conaffinity="0" group="1" material="robot0_Mtl5.008" mesh="robot0_l6_1"/>
                      <geom name="robot0_g46_vis" type="mesh" contype="0" conaffinity="0" group="1" material="robot0_Mtl4.010" mesh="robot0_l6_2"/>
                      <geom name="robot0_g47_vis" type="mesh" contype="0" conaffinity="0" group="1" material="robot0_Mtl3.011" mesh="robot0_l6_3"/>
                      <geom name="robot0_g48_vis" type="mesh" contype="0" conaffinity="0" group="1" material="robot0_Mtl2.012" mesh="robot0_l6_4"/>
                      <geom name="robot0_g49_vis" type="mesh" contype="0" conaffinity="0" group="1" material="robot0_Mtl1.012" mesh="robot0_l6_5"/>
                      <geom name="robot0_link6_collision" size="0.055 0.025" pos="0 0.015 -0.01" type="cylinder" rgba="0 0.5 0 1"/>
                      <body name="robot0_right_hand" pos="0 0 0.024" quat="0.707105 0 0 0.707108">
                        <camera name="robot0_eye_in_hand" pos="0.05 0 0" quat="0 0.707107 0.707107 0" fovy="75"/>
                        <body name="gripper0_gripper_base">
                          <inertial pos="0 0 0" quat="-0.5 0.5 0.5 0.5" mass="0.3" diaginertia="3e-08 2e-08 2e-08"/>
                          <geom name="gripper0_g0_vis" pos="0 0 0.0018" quat="0.707107 0 0 0.707107" type="mesh" contype="0" conaffinity="0" group="1" material="gripper0_Material_001" mesh="gripper0_connector_plate"/>
                          <geom name="gripper0_g1_vis" pos="0 0 0.0194" quat="0.707107 0 0 0.707107" type="mesh" contype="0" conaffinity="0" group="1" material="gripper0_Material_002" mesh="gripper0_electric_gripper_base_0"/>
                          <geom name="gripper0_g2_vis" pos="0 0 0.0194" quat="0.707107 0 0 0.707107" type="mesh" contype="0" conaffinity="0" group="1" material="gripper0_Material_001.001" mesh="gripper0_electric_gripper_base_1"/>
                          <geom name="gripper0_gripper_base_col" size="0.029 0.05" pos="0.004 0 0.04" quat="0 0 0.707107 0.707107" type="cylinder" rgba="0 0 0.5 1"/>
                          <site name="gripper0_ft_frame" pos="0 0 0" size="0.01" group="1" rgba="1 0 0 -1"/>
                          <body name="gripper0_eef" pos="0 0 0.109" quat="0.707107 0 0 -0.707107">
                            <site name="gripper0_grip_site" pos="0 0 0" size="0.01" group="1" rgba="1 0 0 -0.5"/>
                            <site name="gripper0_ee_x" pos="0.1 0 0" quat="0.707105 0 0.707108 0" size="0.005 0.1" group="1" type="cylinder" rgba="1 0 0 0"/>
                            <site name="gripper0_ee_y" pos="0 0.1 0" quat="0.707105 0.707108 0 0" size="0.005 0.1" group="1" type="cylinder" rgba="0 1 0 0"/>
                            <site name="gripper0_ee_z" pos="0 0 0.1" size="0.005 0.1" group="1" type="cylinder" rgba="0 0 1 0"/>
                            <site name="gripper0_grip_site_cylinder" pos="0 0 0" size="0.005 10" group="1" type="cylinder" rgba="0 1 0 -0.3"/>
                          </body>
                          <body name="gripper0_l_finger" pos="0 0.01 0.0444">
                            <inertial pos="0 0 0" quat="0 0 0 -1" mass="0.02" diaginertia="0.01 0.01 0.01"/>
                            <joint name="gripper0_l_finger_joint" pos="0 0 0" axis="0 1 0" type="slide" range="-0.0115 0.020833" armature="1" damping="100" frictionloss="1"/>
                            <geom name="gripper0_l_finger" quat="0 0 0 -1" type="mesh" contype="0" conaffinity="0" group="1" material="gripper0_finger_mat" mesh="gripper0_standard_narrow"/>
                            <geom name="gripper0_l_finger_g0" size="0.005 0.00675 0.0375" pos="0 0.01725 0.04" quat="0 0 0 -1" type="box" contype="0" friction="0 0 0" rgba="0 0 0.5 1"/>
                            <geom name="gripper0_l_finger_g1" size="0.005 0.025 0.0085" pos="-0.005 -0.003 0.0083" quat="0 0 0 -1" type="box" contype="0" friction="0 0 0" rgba="0 0 0.5 1"/>
                            <body name="gripper0_l_finger_tip" pos="0 0.01725 0.075">
                              <inertial pos="0 0 0" quat="0 0 0 1" mass="0.01" diaginertia="0.01 0.01 0.01"/>
                              <geom name="gripper0_l_fingertip_g0_vis" quat="0 0 0 1" type="mesh" contype="0" conaffinity="0" group="1" material="gripper0_finger_mat" mesh="gripper0_half_round_tip"/>
                              <geom name="gripper0_l_fingertip_g0" size="0.004 0.004 0.0185" pos="0 -0.0045 -0.015" quat="0 0 0 -1" type="box" contype="0" friction="0 0 0" rgba="0 0 0.5 1"/>
                              <geom name="gripper0_l_fingerpad_g0" size="0.0035 0.004 0.0165" pos="0 -0.0047 -0.017" type="box" contype="0" friction="0 0 0" rgba="0 0 0.5 1"/>
                            </body>
                          </body>
                          <body name="gripper0_r_finger" pos="0 -0.01 0.0444">
                            <inertial pos="0 0 0" mass="0.02" diaginertia="0.01 0.01 0.01"/>
                            <joint name="gripper0_r_finger_joint" pos="0 0 0" axis="0 1 0" type="slide" range="-0.020833 0.0115" armature="1" damping="100" frictionloss="1"/>
                            <geom name="gripper0_r_finger" type="mesh" contype="0" conaffinity="0" group="1" material="gripper0_finger_mat" mesh="gripper0_standard_narrow"/>
                            <geom name="gripper0_r_finger_g0" size="0.005 0.00675 0.0375" pos="0 -0.01725 0.04" type="box" contype="0" friction="0 0 0" rgba="0 0 0.5 1"/>
                            <geom name="gripper0_r_finger_g1" size="0.005 0.025 0.0085" pos="0.005 0.003 0.0083" type="box" contype="0" friction="0 0 0" rgba="0 0 0.5 1"/>
                            <body name="gripper0_r_finger_tip" pos="0 -0.01725 0.075">
                              <inertial pos="0 0 0" mass="0.01" diaginertia="0.01 0.01 0.01"/>
                              <geom name="gripper0_r_fingertip_g0_vis" type="mesh" contype="0" conaffinity="0" group="1" material="gripper0_finger_mat" mesh="gripper0_half_round_tip"/>
                              <geom name="gripper0_r_fingertip_g0" size="0.004 0.004 0.0185" pos="0 0.0045 -0.015" type="box" contype="0" friction="0 0 0" rgba="0 0 0.5 1"/>
                              <geom name="gripper0_r_fingerpad_g0" size="0.0035 0.004 0.0165" pos="0 0.0047 -0.017" type="box" contype="0" friction="0 0 0" rgba="0 0 0.5 1"/>
                            </body>
                          </body>
                        </body>
                      </body>
                    </body>
                  </body>
                  <body name="robot0_right_l4_2">
                    <inertial pos="1e-08 1e-08 1e-08" quat="0.820473 0.339851 -0.17592 0.424708" mass="1e-08" diaginertia="1e-08 1e-08 1e-08"/>
                    <geom name="robot0_right_l4_2" size="0.06" pos="0 0.01 0.26" rgba="0 0.5 0 1"/>
                  </body>
                </body>
              </body>
              <body name="robot0_right_l2_2">
                <inertial pos="1e-08 1e-08 1e-08" quat="0.820473 0.339851 -0.17592 0.424708" mass="1e-08" diaginertia="1e-08 1e-08 1e-08"/>
                <geom name="robot0_right_l2_2" size="0.06" pos="0 0 0.26" rgba="0 0.5 0 1"/>
              </body>
            </body>
            <body name="robot0_right_l1_2">
              <inertial pos="1e-08 1e-08 1e-08" quat="0.820473 0.339851 -0.17592 0.424708" mass="1e-08" diaginertia="1e-08 1e-08 1e-08"/>
              <geom name="robot0_right_l1_2" size="0.07 0.07" pos="0 0 0.035" type="cylinder" rgba="0 0.5 0 1"/>
            </body>
          </body>
        </body>
      </body>
      <body name="mount0_base" pos="0 0 0.01">
        <body name="mount0_controller_box">
          <inertial pos="-0.325 0 -0.38" mass="46.64" diaginertia="1.71363 1.27988 0.809981"/>
          <geom name="mount0_controller_box_col" size="0.11 0.2 0.265" pos="-0.325 0 -0.38" type="box" rgba="0.5 0.5 0 1"/>
        </body>
        <body name="mount0_pedestal_feet">
          <inertial pos="-0.1225 0 -0.758" mass="167.09" diaginertia="8.16095 9.59375 15.0785"/>
          <geom name="mount0_pedestal_feet_col" size="0.385 0.35 0.155" pos="-0.1225 0 -0.758" type="box" rgba="0.5 0.5 0 1"/>
        </body>
        <body name="mount0_torso">
          <inertial pos="0 0 0" mass="0.0001" diaginertia="1e-08 1e-08 1e-08"/>
          <geom name="mount0_torso_vis" size="0.05 0.05 0.05" pos="0 0 -0.05" type="box" contype="0" conaffinity="0" group="1" rgba="0.2 0.2 0.2 1"/>
        </body>
        <body name="mount0_pedestal">
          <inertial pos="0 0 0" quat="0.659267 -0.259505 -0.260945 0.655692" mass="60.864" diaginertia="6.0869 5.81635 4.20915"/>
          <geom name="mount0_pedestal_vis" type="mesh" contype="0" conaffinity="0" group="1" rgba="0.2 0.2 0.2 1" mesh="mount0_pedestal"/>
          <geom name="mount0_pedestal_col" size="0.18 0.31" pos="-0.02 0 -0.29" type="cylinder" rgba="0.5 0.5 0 1"/>
        </body>
      </body>
    </body>
    <body name="cube_main">
      <joint name="cube_joint0" type="free"/>
      <geom name="cube_g0" size="0.0215355 0.0209927 0.021311" type="box" rgba="0.5 0 0 1"/>
      <geom name="cube_g0_vis" size="0.0215355 0.0209927 0.021311" type="box" contype="0" conaffinity="0" group="1" mass="0" material="cube_redwood_mat"/>
      <site name="cube_default_site" pos="0 0 0" size="0.002" rgba="1 0 0 -1"/>
    </body>
    <body name="bottle_main">
      <joint name="bottle_joint0" type="free" damping="0.0005"/>
      <geom name="bottle_g0" type="mesh" contype="0" conaffinity="0" group="1" friction="0.95 0.3 0.1" solref="0.001 1" solimp="0.998 0.998 0.001 0.5 2" density="50" material="bottle_glass" mesh="bottle_mesh"/>
      <geom name="bottle_g1" type="mesh" friction="0.95 0.3 0.1" solref="0.001 1" solimp="0.998 0.998 0.001 0.5 2" density="50" rgba="0.5 0 0 1" mesh="bottle_mesh"/>
      <geom name="bottle_g1_visual" type="mesh" contype="0" conaffinity="0" group="1" friction="0.95 0.3 0.1" solref="0.001 1" solimp="0.998 0.998 0.001 0.5 2" mass="0" material="bottle_glass" mesh="bottle_mesh"/>
      <site name="bottle_default_site" pos="0 0 0" size="0.002" rgba="1 0 0 0"/>
    </body>
  </worldbody>
  <actuator>
    <general name="robot0_torq_right_j0" joint="robot0_right_j0" ctrlrange="-80 80"/>
    <general name="robot0_torq_right_j1" joint="robot0_right_j1" ctrlrange="-80 80"/>
    <general name="robot0_torq_right_j2" joint="robot0_right_j2" ctrlrange="-40 40"/>
    <general name="robot0_torq_right_j3" joint="robot0_right_j3" ctrlrange="-40 40"/>
    <general name="robot0_torq_right_j4" joint="robot0_right_j4" ctrlrange="-9 9"/>
    <general name="robot0_torq_right_j5" joint="robot0_right_j5" ctrlrange="-9 9"/>
    <general name="robot0_torq_right_j6" joint="robot0_right_j6" ctrlrange="-9 9"/>
    <general name="gripper0_gripper_r_finger_joint" joint="gripper0_r_finger_joint" ctrlrange="-0.0115 0.020833" forcerange="-20 20" biastype="affine" gainprm="1000 0 0 0 0 0 0 0 0 0" biasprm="0 -1000 0 0 0 0 0 0 0 0"/>
    <general name="gripper0_gripper_l_finger_joint" joint="gripper0_l_finger_joint" ctrlrange="-0.020833 0.0115" forcerange="-20 20" biastype="affine" gainprm="1000 0 0 0 0 0 0 0 0 0" biasprm="0 -1000 0 0 0 0 0 0 0 0"/>
  </actuator>
  <sensor>
    <force site="gripper0_ft_frame" name="gripper0_force_ee"/>
    <torque site="gripper0_ft_frame" name="gripper0_torque_ee"/>
  </sensor>
</mujoco>
